Workbook

Sheet Hoja4
A1: Equipo 1 Ganador | D1: Equipo 2 Ganador | G1: Empates
A3: Etiquetas de fila | B3: Suma de GanoEquipo1 | D3: Etiquetas de fila | E3: Suma de GanoEquipo2 | G3: Etiquetas de fila | H3: Suma de Empate
A4: ArgentinaBolivia | B4: 10 | D4: BoliviaArgentina | E4: 2 | G4: ArgentinaBolivia | H4: 2
A5: ArgentinaBrazil | B5: 15 | D5: BrazilArgentina | E5: 9 | G5: ArgentinaBrazil | H5: 8
A6: ArgentinaChile | B6: 18 | D6: BrazilBolivia | E6: 8 | G6: ArgentinaChile | H6: 6
A7: ArgentinaColombia | B7: 7 | D7: BrazilChile | E7: 16 | G7: ArgentinaColombia | H7: 3
A8: ArgentinaCosta Rica | B8: 1 | D8: BrazilColombia | E8: 7 | G8: ArgentinaCosta Rica | H8: 0
A9: ArgentinaEcuador | B9: 10 | D9: BrazilEcuador | E9: 12 | G9: ArgentinaEcuador | H9: 5
A10: ArgentinaJamaica | B10: 1 | D10: BrazilParaguay | E10: 13 | G10: ArgentinaJamaica | H10: 0
A11: ArgentinaMexico | B11: 2 | D11: BrazilPeru | E11: 11 | G11: ArgentinaMexico | H11: 1
A12: ArgentinaParaguay | B12: 18 | D12: BrazilUruguay | E12: 9 | G12: ArgentinaParaguay | H12: 5
A13: ArgentinaPeru | B13: 12 | D13: BrazilVenezuela | E13: 5 | G13: ArgentinaPeru | H13: 2
A14: ArgentinaUnited States | B14: 1 | D14: ChileArgentina | E14: 0 | G14: ArgentinaUnited States | H14: 0
A15: ArgentinaUruguay | B15: 14 | D15: ChileBolivia | E15: 8 | G15: ArgentinaUruguay | H15: 4
... A88: Total general | B88: 294 | D88: Total general | E88: 299 | G88: Total general | H88: 153

Sheet Hoja1
A1: Fecha | B1: Equipo1 | C1: Equipo2 | D1: Marcador | E1: Ciudad | F1: Torneo | G1: Fixture | H1: GolE1 | I1: GolE2 | J1: Copa_América | K1: id1 | L1: id2 | M1: GanoEquipo1 | N1: GanoEquipo2 | O1: Empate
A2: 6028 | B2: Chile | C2: Uruguay | D2: 0 - 4 | E2: Buenos Aires, Arg | F2: Copa América | G2: Chile vs Uruguay | H2: 0 | I2: 4 | J2: 1 | K2: =CONCATENATE(B2,C2) -> ChileUruguay | L2: =CONCATENATE(C2,B2) -> UruguayChile | M2: =IF(H2>I2,1,0) -> 0 | N2: =IF(I2>H2,1,0) -> 1 | O2: =IF(I2=H2,1,0) -> 0
A3: 6032 | B3: Argentina | C3: Chile | D3: 42010 | E3: Buenos Aires | F3: Copa América | G3: Argentina vs Chile | H3: 6 | I3: 1 | J3: 1 | K3: =CONCATENATE(B3,C3) -> ArgentinaChile | L3: =CONCATENATE(C3,B3) -> ChileArgentina | M3: =IF(H3>I3,1,0) -> 1 | N3: =IF(I3>H3,1,0) -> 0 | O3: =IF(I3=H3,1,0) -> 0
A4: 6034 | B4: Chile | C4: Brazil | D4: 42005 | E4: Buenos Aires, Arg | F4: Copa América | G4: Chile vs Brazil | H4: 1 | I4: 1 | J4: 1 | K4: =CONCATENATE(B4,C4) -> ChileBrazil | L4: =CONCATENATE(C4,B4) -> BrazilChile | M4: =IF(H4>I4,1,0) -> 0 | N4: =IF(I4>H4,1,0) -> 0 | O4: =IF(I4=H4,1,0) -> 1
A5: 6036 | B5: Argentina | C5: Brazil | D5: 42005 | E5: Buenos Aires | F5: Copa América | G5: Argentina vs Brazil | H5: 1 | I5: 1 | J5: 1 | K5: =CONCATENATE(B5,C5) -> ArgentinaBrazil | L5: =CONCATENATE(C5,B5) -> BrazilArgentina | M5: =IF(H5>I5,1,0) -> 0 | N5: =IF(I5>H5,1,0) -> 0 | O5: =IF(I5=H5,1,0) -> 1
A6: 6038 | B6: Uruguay | C6: Brazil | D6: 42006 | E6: Buenos Aires, ARG | F6: Copa América | G6: Uruguay vs Brazil | H6: 2 | I6: 1 | J6: 1 | K6: =CONCATENATE(B6,C6) -> UruguayBrazil | L6: =CONCATENATE(C6,B6) -> BrazilUruguay | M6: =IF(H6>I6,1,0) -> 1 | N6: =IF(I6>H6,1,0) -> 0 | O6: =IF(I6=H6,1,0) -> 0
A7: 6043 | B7: Argentina | C7: Uruguay | D7: 0 - 0 | E7: Avellaneda | F7: Copa América | G7: Argentina vs Uruguay | H7: 0 | I7: 0 | J7: 1 | K7: =CONCATENATE(B7,C7) -> ArgentinaUruguay | L7: =CONCATENATE(C7,B7) -> UruguayArgentina | M7: =IF(H7>I7,1,0) -> 0 | N7: =IF(I7>H7,1,0) -> 0 | O7: =IF(I7=H7,1,0) -> 1
A8: 6483 | B8: Chile | C8: Uruguay | D8: 0 - 4 | E8: Montevideo, Uru | F8: Copa América | G8: Chile vs Uruguay | H8: 0 | I8: 4 | J8: 2 | K8: =CONCATENATE(B8,C8) -> ChileUruguay | L8: =CONCATENATE(C8,B8) -> UruguayChile | M8: =IF(H8>I8,1,0) -> 0 | N8: =IF(I8>H8,1,0) -> 1 | O8: =IF(I8=H8,1,0) -> 0
A9: 6486 | B9: Argentina | C9: Brazil | D9: 42039 | E9: Montevideo | F9: Copa América | G9: Argentina vs Brazil | H9: 4 | I9: 2 | J9: 2 | K9: =CONCATENATE(B9,C9) -> ArgentinaBrazil | L9: =CONCATENATE(C9,B9) -> BrazilArgentina | M9: =IF(H9>I9,1,0) -> 1 | N9: =IF(I9>H9,1,0) -> 0 | O9: =IF(I9=H9,1,0) -> 0
A10: 6489 | B10: Argentina | C10: Chile | D10: 1 - 0 | E10: Montevideo | F10: Copa América | G10: Argentina vs Chile | H10: 1 | I10: 0 | J10: 2 | K10: =CONCATENATE(B10,C10) -> ArgentinaChile | L10: =CONCATENATE(C10,B10) -> ChileArgentina | M10: =IF(H10>I10,1,0) -> 1 | N10: =IF(I10>H10,1,0) -> 0 | O10: =IF(I10=H10,1,0) -> 0
A11: 6490 | B11: Uruguay | C11: Brazil | D11: 4 - 0 | E11: Montevideo, URU | F11: Copa América | G11: Uruguay vs Brazil | H11: 4 | I11: 0 | J11: 2 | K11: =CONCATENATE(B11,C11) -> UruguayBrazil | L11: =CONCATENATE(C11,B11) -> BrazilUruguay | M11: =IF(H11>I11,1,0) -> 1 | N11: =IF(I11>H11,1,0) -> 0 | O11: =IF(I11=H11,1,0) -> 0
A12: 6495 | B12: Chile | C12: Brazil | D12: 0 - 5 | E12: Montevideo, Uru | F12: Copa América | G12: Chile vs Brazil | H12: 0 | I12: 5 | J12: 2 | K12: =CONCATENATE(B12,C12) -> ChileBrazil | L12: =CONCATENATE(C12,B12) -> BrazilChile | M12: =IF(H12>I12,1,0) -> 0 | N12: =IF(I12>H12,1,0) -> 1 | O12: =IF(I12=H12,1,0) -> 0
A13: 6497 | B13: Argentina | C13: Uruguay | D13: 0 - 1 | E13: Montevideo | F13: Copa América | G13: Argentina vs Uruguay | H13: 0 | I13: 1 | J13: 2 | K13: =CONCATENATE(B13,C13) -> ArgentinaUruguay | L13: =CONCATENATE(C13,B13) -> UruguayArgentina | M13: =IF(H13>I13,1,0) -> 0 | N13: =IF(I13>H13,1,0) -> 1 | O13: =IF(I13=H13,1,0) -> 0
A14: 7071 | B14: Chile | C14: Brazil | D14: 0 - 6 | E14: Rio de Janeiro, Bra | F14: Copa América | G14: Chile vs Brazil | H14: 0 | I14: 6 | J14: 3 | K14: =CONCATENATE(B14,C14) -> ChileBrazil | L14: =CONCATENATE(C14,B14) -> BrazilChile | M14: =IF(H14>I14,1,0) -> 0 | N14: =IF(I14>H14,1,0) -> 1 | O14: =IF(I14=H14,1,0) -> 0
A15: 7073 | B15: Argentina | C15: Uruguay | D15: 42065 | E15: Rio de Janeiro | F15: Copa América | G15: Argentina vs Uruguay | H15: 2 | I15: 3 | J15: 3 | K15: =CONCATENATE(B15,C15) -> ArgentinaUruguay | L15: =CONCATENATE(C15,B15) -> UruguayArgentina | M15: =IF(H15>I15,1,0) -> 0 | N15: =IF(I15>H15,1,0) -> 1 | O15: =IF(I15=H15,1,0) -> 0
A16: 7077 | B16: Chile | C16: Uruguay | D16: 0 - 2 | E16: Rio de Janeiro, Bra | F16: Copa América | G16: Chile vs Uruguay | H16: 0 | I16: 2 | J16: 3 | K16: =CONCATENATE(B16,C16) -> ChileUruguay | L16: =CONCATENATE(C16,B16) -> UruguayChile | M16: =IF(H16>I16,1,0) -> 0 | N16: =IF(I16>H16,1,0) -> 1 | O16: =IF(I16=H16,1,0) -> 0
A17: 7078 | B17: Argentina | C17: Brazil | D17: 42064 | E17: Rio de Janeiro | F17: Copa América | G17: Argentina vs Brazil | H17: 1 | I17: 3 | J17: 3 | K17: =CONCATENATE(B17,C17) -> ArgentinaBrazil | L17: =CONCATENATE(C17,B17) -> BrazilArgentina | M17: =IF(H17>I17,1,0) -> 0 | N17: =IF(I17>H17,1,0) -> 1 | O17: =IF(I17=H17,1,0) -> 0
A18: 7082 | B18: Argentina | C18: Chile | D18: 42008 | E18: Rio de Janeiro | F18: Copa América | G18: Argentina vs Chile | H18: 4 | I18: 1 | J18: 3 | K18: =CONCATENATE(B18,C18) -> ArgentinaChile | L18: =CONCATENATE(C18,B18) -> ChileArgentina | M18: =IF(H18>I18,1,0) -> 1 | N18: =IF(I18>H18,1,0) -> 0 | O18: =IF(I18=H18,1,0) -> 0
A19: 7085 | B19: Uruguay | C19: Brazil | D19: 42037 | E19: Río de Janeiro, BRA | F19: Copa América | G19: Uruguay vs Brazil | H19: 2 | I19: 2 | J19: 3 | K19: =CONCATENATE(B19,C19) -> UruguayBrazil | L19: =CONCATENATE(C19,B19) -> BrazilUruguay | M19: =IF(H19>I19,1,0) -> 0 | N19: =IF(I19>H19,1,0) -> 0 | O19: =IF(I19=H19,1,0) -> 1
A20: 7089 | B20: Uruguay | C20: Brazil | D20: 0 - 1 | E20: Río de Janeiro, BRA | F20: Copa América | G20: Uruguay vs Brazil | H20: 0 | I20: 1 | J20: 3 | K20: =CONCATENATE(B20,C20) -> UruguayBrazil | L20: =CONCATENATE(C20,B20) -> BrazilUruguay | M20: =IF(H20>I20,1,0) -> 0 | N20: =IF(I20>H20,1,0) -> 1 | O20: =IF(I20=H20,1,0) -> 0
A21: 7560 | B21: Chile | C21: Brazil | D21: 0 - 1 | E21: Viña del Mar | F21: Copa América | G21: Chile vs Brazil | H21: 0 | I21: 1 | J21: 4 | K21: =CONCATENATE(B21,C21) -> ChileBrazil | L21: =CONCATENATE(C21,B21) -> BrazilChile | M21: =IF(H21>I21,1,0) -> 0 | N21: =IF(I21>H21,1,0) -> 1 | O21: =IF(I21=H21,1,0) -> 0
A22: 7561 | B22: Argentina | C22: Uruguay | D22: 42005 | E22: Viña del Mar | F22: Copa América | G22: Argentina vs Uruguay | H22: 1 | I22: 1 | J22: 4 | K22: =CONCATENATE(B22,C22) -> ArgentinaUruguay | L22: =CONCATENATE(C22,B22) -> UruguayArgentina | M22: =IF(H22>I22,1,0) -> 0 | N22: =IF(I22>H22,1,0) -> 0 | O22: =IF(I22=H22,1,0) -> 1
A23: 7567 | B23: Uruguay | C23: Brazil | D23: 6 - 0 | E23: Valparaíso, CHI | F23: Copa América | G23: Uruguay vs Brazil | H23: 6 | I23: 0 | J23: 4 | K23: =CONCATENATE(B23,C23) -> UruguayBrazil | L23: =CONCATENATE(C23,B23) -> BrazilUruguay | M23: =IF(H23>I23,1,0) -> 1 | N23: =IF(I23>H23,1,0) -> 0 | O23: =IF(I23=H23,1,0) -> 0
A24: 7569 | B24: Argentina | C24: Chile | D24: 42005 | E24: Viña del Mar | F24: Copa América | G24: Argentina vs Chile | H24: 1 | I24: 1 | J24: 4 | K24: =CONCATENATE(B24,C24) -> ArgentinaChile | L24: =CONCATENATE(C24,B24) -> ChileArgentina | M24: =IF(H24>I24,1,0) -> 0 | N24: =IF(I24>H24,1,0) -> 0 | O24: =IF(I24=H24,1,0) -> 1
A25: 7574 | B25: Argentina | C25: Brazil | D25: 2 - 0 | E25: Viña del Mar | F25: Copa América | G25: Argentina vs Brazil | H25: 2 | I25: 0 | J25: 4 | K25: =CONCATENATE(B25,C25) -> ArgentinaBrazil | L25: =CONCATENATE(C25,B25) -> BrazilArgentina | M25: =IF(H25>I25,1,0) -> 1 | N25: =IF(I25>H25,1,0) -> 0 | O25: =IF(I25=H25,1,0) -> 0
A26: 7575 | B26: Chile | C26: Uruguay | D26: 42036 | E26: Viña del Mar | F26: Copa América | G26: Chile vs Uruguay | H26: 1 | I26: 2 | J26: 4 | K26: =CONCATENATE(B26,C26) -> ChileUruguay | L26: =CONCATENATE(C26,B26) -> UruguayChile | M26: =IF(H26>I26,1,0) -> 0 | N26: =IF(I26>H26,1,0) -> 1 | O26: =IF(I26=H26,1,0) -> 0
A27: 7946 | B27: Argentina | C27: Brazil | D27: 1 - 0 | E27: Buenos Aires | F27: Copa América | G27: Argentina vs Brazil | H27: 1 | I27: 0 | J27: 5 | K27: =CONCATENATE(B27,C27) -> ArgentinaBrazil | L27: =CONCATENATE(C27,B27) -> BrazilArgentina | M27: =IF(H27>I27,1,0) -> 1 | N27: =IF(I27>H27,1,0) -> 0 | O27: =IF(I27=H27,1,0) -> 0
A28: 7953 | B28: Paraguay | C28: Uruguay | D28: 42006 | E28: Buenos Aires, Arg | F28: Copa América | G28: Paraguay vs Uruguay | H28: 2 | I28: 1 | J28: 5 | K28: =CONCATENATE(B28,C28) -> ParaguayUruguay | L28: =CONCATENATE(C28,B28) -> UruguayParaguay | M28: =IF(H28>I28,1,0) -> 1 | N28: =IF(I28>H28,1,0) -> 0 | O28: =IF(I28=H28,1,0) -> 0
A29: 7956 | B29: Paraguay | C29: Brazil | D29: 0 - 3 | E29: Buenos Aires, Arg | F29: Copa América | G29: Paraguay vs Brazil | H29: 0 | I29: 3 | J29: 5 | K29: =CONCATENATE(B29,C29) -> ParaguayBrazil | L29: =CONCATENATE(C29,B29) -> BrazilParaguay | M29: =IF(H29>I29,1,0) -> 0 | N29: =IF(I29>H29,1,0) -> 1 | O29: =IF(I29=H29,1,0) -> 0
A30: 7960 | B30: Argentina | C30: Paraguay | D30: 3 - 0 | E30: Buenos Aires | F30: Copa América | G30: Argentina vs Paraguay | H30: 3 | I30: 0 | J30: 5 | K30: =CONCATENATE(B30,C30) -> ArgentinaParaguay | L30: =CONCATENATE(C30,B30) -> ParaguayArgentina | M30: =IF(H30>I30,1,0) -> 1 | N30: =IF(I30>H30,1,0) -> 0 | O30: =IF(I30=H30,1,0) -> 0
A31: 7967 | B31: Uruguay | C31: Brazil | D31: 42006 | E31: Buenos Aires, ARG | F31: Copa América | G31: Uruguay vs Brazil | H31: 2 | I31: 1 | J31: 5 | K31: =CONCATENATE(B31,C31) -> UruguayBrazil | L31: =CONCATENATE(C31,B31) -> BrazilUruguay | M31: =IF(H31>I31,1,0) -> 1 | N31: =IF(I31>H31,1,0) -> 0 | O31: =IF(I31=H31,1,0) -> 0
A32: 7974 | B32: Argentina | C32: Uruguay | D32: 1 - 0 | E32: Buenos Aires | F32: Copa América | G32: Argentina vs Uruguay | H32: 1 | I32: 0 | J32: 5 | K32: =CONCATENATE(B32,C32) -> ArgentinaUruguay | L32: =CONCATENATE(C32,B32) -> UruguayArgentina | M32: =IF(H32>I32,1,0) -> 1 | N32: =IF(I32>H32,1,0) -> 0 | O32: =IF(I32=H32,1,0) -> 0
A33: 8296 | B33: Chile | C33: Brazil | D33: 42005 | E33: Rio de Janeiro, Bra | F33: Copa América | G33: Chile vs Brazil | H33: 1 | I33: 1 | J33: 6 | K33: =CONCATENATE(B33,C33) -> ChileBrazil | L33: =CONCATENATE(C33,B33) -> BrazilChile | M33: =IF(H33>I33,1,0) -> 0 | N33: =IF(I33>H33,1,0) -> 0 | O33: =IF(I33=H33,1,0) -> 1
A34: 8302 | B34: Chile | C34: Uruguay | D34: 0 - 2 | E34: Rio de Janeiro, Bra | F34: Copa América | G34: Chile vs Uruguay | H34: 0 | I34: 2 | J34: 6 | K34: =CONCATENATE(B34,C34) -> ChileUruguay | L34: =CONCATENATE(C34,B34) -> UruguayChile | M34: =IF(H34>I34,1,0) -> 0 | N34: =IF(I34>H34,1,0) -> 1 | O34: =IF(I34=H34,1,0) -> 0
A35: 8303 | B35: Paraguay | C35: Brazil | D35: 42005 | E35: Rio de Janeiro, Bra | F35: Copa América | G35: Paraguay vs Brazil | H35: 1 | I35: 1 | J35: 6 | K35: =CONCATENATE(B35,C35) -> ParaguayBrazil | L35: =CONCATENATE(C35,B35) -> BrazilParaguay | M35: =IF(H35>I35,1,0) -> 0 | N35: =IF(I35>H35,1,0) -> 0 | O35: =IF(I35=H35,1,0) -> 1
A36: 8307 | B36: Argentina | C36: Chile | D36: 4 - 0 | E36: Rio de Janeiro | F36: Copa América | G36: Argentina vs Chile | H36: 4 | I36: 0 | J36: 6 | K36: =CONCATENATE(B36,C36) -> ArgentinaChile | L36: =CONCATENATE(C36,B36) -> ChileArgentina | M36: =IF(H36>I36,1,0) -> 1 | N36: =IF(I36>H36,1,0) -> 0 | O36: =IF(I36=H36,1,0) -> 0
A37: 8310 | B37: Uruguay | C37: Brazil | D37: 0 - 0 | E37: Río de Janeiro, BRA | F37: Copa América | G37: Uruguay vs Brazil | H37: 0 | I37: 0 | J37: 6 | K37: =CONCATENATE(B37,C37) -> UruguayBrazil | L37: =CONCATENATE(C37,B37) -> BrazilUruguay | M37: =IF(H37>I37,1,0) -> 0 | N37: =IF(I37>H37,1,0) -> 0 | O37: =IF(I37=H37,1,0) -> 1
A38: 8314 | B38: Chile | C38: Paraguay | D38: 0 - 3 | E38: Rio de Janeiro, Bra | F38: Copa América | G38: Chile vs Paraguay | H38: 0 | I38: 3 | J38: 6 | K38: =CONCATENATE(B38,C38) -> ChileParaguay | L38: =CONCATENATE(C38,B38) -> ParaguayChile | M38: =IF(H38>I38,1,0) -> 0 | N38: =IF(I38>H38,1,0) -> 1 | O38: =IF(I38=H38,1,0) -> 0
A39: 8317 | B39: Argentina | C39: Uruguay | D39: 0 - 1 | E39: Rio de Janeiro | F39: Copa América | G39: Argentina vs Uruguay | H39: 0 | I39: 1 | J39: 6 | K39: =CONCATENATE(B39,C39) -> ArgentinaUruguay | L39: =CONCATENATE(C39,B39) -> UruguayArgentina | M39: =IF(H39>I39,1,0) -> 0 | N39: =IF(I39>H39,1,0) -> 1 | O39: =IF(I39=H39,1,0) -> 0
A40: 8321 | B40: Paraguay | C40: Uruguay | D40: 1 - 0 | E40: Rio de Janeiro, Bra | F40: Copa América | G40: Paraguay vs Uruguay | H40: 1 | I40: 0 | J40: 6 | K40: =CONCATENATE(B40,C40) -> ParaguayUruguay | L40: =CONCATENATE(C40,B40) -> UruguayParaguay | M40: =IF(H40>I40,1,0) -> 1 | N40: =IF(I40>H40,1,0) -> 0 | O40: =IF(I40=H40,1,0) -> 0
...

Sheet Hoja2

Sheet Paises
A1: Etiquetas de fila | B1: Etiquetas de fila
A2: Argentina | B2: Bolivia | D2: Argentina
A3: Bolivia | B3: Brazil | D3: Bolivia
A4: Brazil | B4: Chile | D4: Brazil
A5: Chile | B5: Colombia | D5: Chile
A6: Colombia | B6: Costa Rica | D6: Colombia
A7: Costa Rica | B7: Ecuador | D7: Costa Rica
A8: Ecuador | B8: Honduras | D8: Ecuador
A9: Paraguay | B9: Jamaica | D9: Honduras
A10: Peru | B10: Japan | D10: Jamaica
A11: Uruguay | B11: Paraguay | D11: Japan
A12: Venezuela | B12: Peru | D12: Mexico
A13: (en blanco) | B13: United States | D13: Paraguay
... A15: Total general | B15: Venezuela | D15: United States
B16: (en blanco) | D16: Uruguay
B17: Mexico | D17: Venezuela
B18: Total general

Sheet Matriz
A1: Partidos Ganados por Equipo 1
C2: Equipo 2
C3: Argentina | D3: Bolivia | E3: Brazil | F3: Chile | G3: Colombia | H3: Costa Rica | I3: Ecuador | J3: Honduras | K3: Jamaica | L3: Japan | M3: Mexico | N3: Paraguay | O3: Peru | P3: United States | Q3: Uruguay | R3: Venezuela | S3: Total Ganados
A4: Equipo 1 | B4: Argentina | D4: =GETPIVOTDATA("Suma de GanoEquipo1",Hoja4!$A$3,"id1",CONCATENATE($B$4,D3)) -> 10 | E4: =GETPIVOTDATA("Suma de GanoEquipo1",Hoja4!$A$3,"id1",CONCATENATE($B$4,E3)) -> 15 | F4: =GETPIVOTDATA("Suma de GanoEquipo1",Hoja4!$A$3,"id1",CONCATENATE($B$4,F3)) -> 18 | G4: =GETPIVOTDATA("Suma de GanoEquipo1",Hoja4!$A$3,"id1",CONCATENATE($B$4,G3)) -> 7 | H4: =GETPIVOTDATA("Suma de GanoEquipo1",Hoja4!$A$3,"id1",CONCATENATE($B$4,H3)) -> 1 | I4: =GETPIVOTDATA("Suma de GanoEquipo1",Hoja4!$A$3,"id1",CONCATENATE($B$4,I3)) -> 10 | K4: =GETPIVOTDATA("Suma de GanoEquipo1",Hoja4!$A$3,"id1",CONCATENATE($B$4,K3)) -> 1 | M4: =GETPIVOTDATA("Suma de GanoEquipo1",Hoja4!$A$3,"id1",CONCATENATE($B$4,M3)) -> 2 | N4: =GETPIVOTDATA("Suma de GanoEquipo1",Hoja4!$A$3,"id1",CONCATENATE($B$4,N3)) -> 18 | O4: =GETPIVOTDATA("Suma de GanoEquipo1",Hoja4!$A$3,"id1",CONCATENATE($B$4,O3)) -> 12 | P4: =GETPIVOTDATA("Suma de GanoEquipo1",Hoja4!$A$3,"id1",CONCATENATE($B$4,P3)) -> 1 | Q4: =GETPIVOTDATA("Suma de GanoEquipo1",Hoja4!$A$3,"id1",CONCATENATE($B$4,Q3)) -> 14 | R4: =GETPIVOTDATA("Suma de GanoEquipo1",Hoja4!$A$3,"id1",CONCATENATE($B$4,R3)) -> 4 | S4: =SUM(C4:R4) -> 113
B5: Bolivia | E5: =GETPIVOTDATA("Suma de GanoEquipo1",Hoja4!$A$3,"id1",CONCATENATE($B$5,E3)) -> 2 | F5: =GETPIVOTDATA("Suma de GanoEquipo1",Hoja4!$A$3,"id1",CONCATENATE($B$5,F3)) -> 2 | G5: =GETPIVOTDATA("Suma de GanoEquipo1",Hoja4!$A$3,"id1",CONCATENATE($B$5,G3)) -> 3 | H5: =GETPIVOTDATA("Suma de GanoEquipo1",Hoja4!$A$3,"id1",CONCATENATE($B$5,H3)) -> 0 | I5: =GETPIVOTDATA("Suma de GanoEquipo1",Hoja4!$A$3,"id1",CONCATENATE($B$5,I3)) -> 2 | J5: =GETPIVOTDATA("Suma de GanoEquipo1",Hoja4!$A$3,"id1",CONCATENATE($B$5,J3)) -> 0 | L5: =GETPIVOTDATA("Suma de GanoEquipo1",Hoja4!$A$3,"id1",CONCATENATE($B$5,L3)) -> 0 | M5: =GETPIVOTDATA("Suma de GanoEquipo1",Hoja4!$A$3,"id1",CONCATENATE($B$5,M3)) -> 1 | N5: =GETPIVOTDATA("Suma de GanoEquipo1",Hoja4!$A$3,"id1",CONCATENATE($B$5,N3)) -> 1 | O5: =GETPIVOTDATA("Suma de GanoEquipo1",Hoja4!$A$3,"id1",CONCATENATE($B$5,O3)) -> 3 | P5: =GETPIVOTDATA("Suma de GanoEquipo1",Hoja4!$A$3,"id1",CONCATENATE($B$5,P3)) -> 1 | Q5: =GETPIVOTDATA("Suma de GanoEquipo1",Hoja4!$A$3,"id1",CONCATENATE($B$5,Q3)) -> 2 | R5: =GETPIVOTDATA("Suma de GanoEquipo1",Hoja4!$A$3,"id1",CONCATENATE($B$5,R3)) -> 1 | S5: =SUM(C5:R5) -> 18
B6: Brazil | H6: =GETPIVOTDATA("Suma de GanoEquipo1",Hoja4!$A$3,"id1",CONCATENATE($B$6,H3)) -> 2 | J6: =GETPIVOTDATA("Suma de GanoEquipo1",Hoja4!$A$3,"id1",CONCATENATE($B$6,J3)) -> 0 | M6: =GETPIVOTDATA("Suma de GanoEquipo1",Hoja4!$A$3,"id1",CONCATENATE($B$6,M3)) -> 4 | P6: =GETPIVOTDATA("Suma de GanoEquipo1",Hoja4!$A$3,"id1",CONCATENATE($B$6,P3)) -> 1 | S6: =SUM(C6:R6) -> 7
B7: Chile | E7: =GETPIVOTDATA("Suma de GanoEquipo1",Hoja4!$A$3,"id1",CONCATENATE($B$7,E3)) -> 3 | G7: =GETPIVOTDATA("Suma de GanoEquipo1",Hoja4!$A$3,"id1",CONCATENATE($B$7,G3)) -> 7 | H7: =GETPIVOTDATA("Suma de GanoEquipo1",Hoja4!$A$3,"id1",CONCATENATE($B$7,H3)) -> 0 | I7: =GETPIVOTDATA("Suma de GanoEquipo1",Hoja4!$A$3,"id1",CONCATENATE($B$7,I3)) -> 12 | M7: =GETPIVOTDATA("Suma de GanoEquipo1",Hoja4!$A$3,"id1",CONCATENATE($B$7,M3)) -> 1 | N7: =GETPIVOTDATA("Suma de GanoEquipo1",Hoja4!$A$3,"id1",CONCATENATE($B$7,N3)) -> 7 | O7: =GETPIVOTDATA("Suma de GanoEquipo1",Hoja4!$A$3,"id1",CONCATENATE($B$7,O3)) -> 7 | P7: =GETPIVOTDATA("Suma de GanoEquipo1",Hoja4!$A$3,"id1",CONCATENATE($B$7,P3)) -> 0 | Q7: =GETPIVOTDATA("Suma de GanoEquipo1",Hoja4!$A$3,"id1",CONCATENATE($B$7,Q3)) -> 6 | R7: =GETPIVOTDATA("Suma de GanoEquipo1",Hoja4!$A$3,"id1",CONCATENATE($B$7,R3)) -> 7 | S7: =SUM(C7:R7) -> 50
B8: Colombia | E8: =GETPIVOTDATA("Suma de GanoEquipo1",Hoja4!$A$3,"id1",CONCATENATE($B$8,E3)) -> 2 | H8: =GETPIVOTDATA("Suma de GanoEquipo1",Hoja4!$A$3,"id1",CONCATENATE($B$8,H3)) -> 3 | I8: =GETPIVOTDATA("Suma de GanoEquipo1",Hoja4!$A$3,"id1",CONCATENATE($B$8,I3)) -> 9 | J8: =GETPIVOTDATA("Suma de GanoEquipo1",Hoja4!$A$3,"id1",CONCATENATE($B$8,J3)) -> 1 | M8: =GETPIVOTDATA("Suma de GanoEquipo1",Hoja4!$A$3,"id1",CONCATENATE($B$8,M3)) -> 2 | N8: =GETPIVOTDATA("Suma de GanoEquipo1",Hoja4!$A$3,"id1",CONCATENATE($B$8,N3)) -> 3 | O8: =GETPIVOTDATA("Suma de GanoEquipo1",Hoja4!$A$3,"id1",CONCATENATE($B$8,O3)) -> 2 | P8: =GETPIVOTDATA("Suma de GanoEquipo1",Hoja4!$A$3,"id1",CONCATENATE($B$8,P3)) -> 2 | Q8: =GETPIVOTDATA("Suma de GanoEquipo1",Hoja4!$A$3,"id1",CONCATENATE($B$8,Q3)) -> 3 | R8: =GETPIVOTDATA("Suma de GanoEquipo1",Hoja4!$A$3,"id1",CONCATENATE($B$8,R3)) -> 4 | S8: =SUM(C8:R8) -> 31
B9: Costa Rica | J9: =GETPIVOTDATA("Suma de GanoEquipo1",Hoja4!$A$3,"id1",CONCATENATE($B$9,J3)) -> 1 | S9: =SUM(C9:R9) -> 1
B10: Ecuador | E10: =GETPIVOTDATA("Suma de GanoEquipo1",Hoja4!$A$3,"id1",CONCATENATE($B$10,E3)) -> 0 | M10: =GETPIVOTDATA("Suma de GanoEquipo1",Hoja4!$A$3,"id1",CONCATENATE($B$10,M3)) -> 0 | N10: =GETPIVOTDATA("Suma de GanoEquipo1",Hoja4!$A$3,"id1",CONCATENATE($B$10,N3)) -> 3 | O10: =GETPIVOTDATA("Suma de GanoEquipo1",Hoja4!$A$3,"id1",CONCATENATE($B$10,O3)) -> 1 | P10: =GETPIVOTDATA("Suma de GanoEquipo1",Hoja4!$A$3,"id1",CONCATENATE($B$10,P3)) -> 1 | Q10: =GETPIVOTDATA("Suma de GanoEquipo1",Hoja4!$A$3,"id1",CONCATENATE($B$10,Q3)) -> 3 | R10: =GETPIVOTDATA("Suma de GanoEquipo1",Hoja4!$A$3,"id1",CONCATENATE($B$10,R3)) -> 2 | S10: =SUM(C10:R10) -> 10
B11: Honduras | S11: =SUM(C11:R11) -> 0
B12: Jamaica | S12: =SUM(C12:R12) -> 0
B13: Japan | S13: =SUM(C13:R13) -> 0
B14: Mexico | H14: =GETPIVOTDATA("Suma de GanoEquipo1",Hoja4!$A$3,"id1",CONCATENATE($B$14,H3)) -> 0 | P14: =GETPIVOTDATA("Suma de GanoEquipo1",Hoja4!$A$3,"id1",CONCATENATE($B$14,P3)) -> 0 | S14: =SUM(C14:R14) -> 0
B15: Paraguay | E15: =GETPIVOTDATA("Suma de GanoEquipo1",Hoja4!$A$3,"id1",CONCATENATE($B$15,E3)) -> 7 | H15: =GETPIVOTDATA("Suma de GanoEquipo1",Hoja4!$A$3,"id1",CONCATENATE($B$15,H3)) -> 1 | K15: =GETPIVOTDATA("Suma de GanoEquipo1",Hoja4!$A$3,"id1",CONCATENATE($B$15,K3)) -> 1 | L15: =GETPIVOTDATA("Suma de GanoEquipo1",Hoja4!$A$3,"id1",CONCATENATE($B$15,L3)) -> 1 | M15: =GETPIVOTDATA("Suma de GanoEquipo1",Hoja4!$A$3,"id1",CONCATENATE($B$15,M3)) -> 1 | O15: =GETPIVOTDATA("Suma de GanoEquipo1",Hoja4!$A$3,"id1",CONCATENATE($B$15,O3)) -> 7 | P15: =GETPIVOTDATA("Suma de GanoEquipo1",Hoja4!$A$3,"id1",CONCATENATE($B$15,P3)) -> 1 | Q15: =GETPIVOTDATA("Suma de GanoEquipo1",Hoja4!$A$3,"id1",CONCATENATE($B$15,Q3)) -> 6 | R15: =GETPIVOTDATA("Suma de GanoEquipo1",Hoja4!$A$3,"id1",CONCATENATE($B$15,R3)) -> 4 | S15: =SUM(C15:R15) -> 29
B16: Peru | E16: =GETPIVOTDATA("Suma de GanoEquipo1",Hoja4!$A$3,"id1",CONCATENATE($B$16,E3)) -> 2 | L16: =GETPIVOTDATA("Suma de GanoEquipo1",Hoja4!$A$3,"id1",CONCATENATE($B$16,L3)) -> 1 | M16: =GETPIVOTDATA("Suma de GanoEquipo1",Hoja4!$A$3,"id1",CONCATENATE($B$16,M3)) -> 2 | Q16: =GETPIVOTDATA("Suma de GanoEquipo1",Hoja4!$A$3,"id1",CONCATENATE($B$16,Q3)) -> 6 | R16: =GETPIVOTDATA("Suma de GanoEquipo1",Hoja4!$A$3,"id1",CONCATENATE($B$16,R3)) -> 5 | S16: =SUM(C16:R16) -> 16
B17: United States | S17: =SUM(C17:R17) -> 0
B18: Uruguay | E18: =GETPIVOTDATA("Suma de GanoEquipo1",Hoja4!$A$3,"id1",CONCATENATE($B$18,E3)) -> 9 | H18: =GETPIVOTDATA("Suma de GanoEquipo1",Hoja4!$A$3,"id1",CONCATENATE($B$18,H3)) -> 1 | J18: =GETPIVOTDATA("Suma de GanoEquipo1",Hoja4!$A$3,"id1",CONCATENATE($B$18,J3)) -> 0 | K18: =GETPIVOTDATA("Suma de GanoEquipo1",Hoja4!$A$3,"id1",CONCATENATE($B$18,K3)) -> 1 | M18: =GETPIVOTDATA("Suma de GanoEquipo1",Hoja4!$A$3,"id1",CONCATENATE($B$18,M3)) -> 1 | P18: =GETPIVOTDATA("Suma de GanoEquipo1",Hoja4!$A$3,"id1",CONCATENATE($B$18,P3)) -> 1 | R18: =GETPIVOTDATA("Suma de GanoEquipo1",Hoja4!$A$3,"id1",CONCATENATE($B$18,R3)) -> 6 | S18: =SUM(C18:R18) -> 19
B19: Venezuela | E19: =GETPIVOTDATA("Suma de GanoEquipo1",Hoja4!$A$3,"id1",CONCATENATE($B$19,E3)) -> 0 | M19: =GETPIVOTDATA("Suma de GanoEquipo1",Hoja4!$A$3,"id1",CONCATENATE($B$19,M3)) -> 0 | P19: =GETPIVOTDATA("Suma de GanoEquipo1",Hoja4!$A$3,"id1",CONCATENATE($B$19,P3)) -> 0 | S19: =SUM(C19:R19) -> 0
A21: Partidos Ganados por Equipo 2
C22: Equipo 1
C23: Argentina | D23: Bolivia | E23: Brazil | F23: Chile | G23: Colombia | H23: Costa Rica | I23: Ecuador | J23: Honduras | K23: Jamaica | L23: Japan | M23: Mexico | N23: Paraguay | O23: Peru | P23: United States | Q23: Uruguay | R23: Venezuela | S23: Total Ganados
A24: Equipo 2 | B24: Argentina | S24: =SUM(C24:R24) -> 0
B25: Bolivia | C25: =GETPIVOTDATA("GanoEquipo2",Hoja4!$D$3,"id2",CONCATENATE($B$25,C23)) -> 2 | S25: =SUM(C25:R25) -> 2
B26: Brazil | C26: =GETPIVOTDATA("GanoEquipo2",Hoja4!$D$3,"id2",CONCATENATE($B$26,C23)) -> 9 | D26: =GETPIVOTDATA("GanoEquipo2",Hoja4!$D$3,"id2",CONCATENATE($B$26,D23)) -> 8 | F26: =GETPIVOTDATA("GanoEquipo2",Hoja4!$D$3,"id2",CONCATENATE($B$26,F23)) -> 16 | G26: =GETPIVOTDATA("GanoEquipo2",Hoja4!$D$3,"id2",CONCATENATE($B$26,G23)) -> 7 | I26: =GETPIVOTDATA("GanoEquipo2",Hoja4!$D$3,"id2",CONCATENATE($B$26,I23)) -> 12 | N26: =GETPIVOTDATA("GanoEquipo2",Hoja4!$D$3,"id2",CONCATENATE($B$26,N23)) -> 13 | O26: =GETPIVOTDATA("GanoEquipo2",Hoja4!$D$3,"id2",CONCATENATE($B$26,O23)) -> 11 | Q26: =GETPIVOTDATA("GanoEquipo2",Hoja4!$D$3,"id2",CONCATENATE($B$26,Q23)) -> 9 | R26: =GETPIVOTDATA("GanoEquipo2",Hoja4!$D$3,"id2",CONCATENATE($B$26,R23)) -> 5 | S26: =SUM(C26:R26) -> 90
B27: Chile | C27: =GETPIVOTDATA("GanoEquipo2",Hoja4!$D$3,"id2",CONCATENATE($B$27,C23)) -> 0 | D27: =GETPIVOTDATA("GanoEquipo2",Hoja4!$D$3,"id2",CONCATENATE($B$27,D23)) -> 8 | S27: =SUM(C27:R27) -> 8
B28: Colombia | C28: =GETPIVOTDATA("GanoEquipo2",Hoja4!$D$3,"id2",CONCATENATE($B$28,C23)) -> 2 | D28: =GETPIVOTDATA("GanoEquipo2",Hoja4!$D$3,"id2",CONCATENATE($B$28,D23)) -> 4 | F28: =GETPIVOTDATA("GanoEquipo2",Hoja4!$D$3,"id2",CONCATENATE($B$28,F23)) -> 2 | S28: =SUM(C28:R28) -> 8
B29: Costa Rica | C29: =GETPIVOTDATA("GanoEquipo2",Hoja4!$D$3,"id2",CONCATENATE($B$29,C23)) -> 0 | D29: =GETPIVOTDATA("GanoEquipo2",Hoja4!$D$3,"id2",CONCATENATE($B$29,D23)) -> 2 | E29: =GETPIVOTDATA("GanoEquipo2",Hoja4!$D$3,"id2",CONCATENATE($B$29,E23)) -> 0 | F29: =GETPIVOTDATA("GanoEquipo2",Hoja4!$D$3,"id2",CONCATENATE($B$29,F23)) -> 1 | G29: =GETPIVOTDATA("GanoEquipo2",Hoja4!$D$3,"id2",CONCATENATE($B$29,G23)) -> 0 | M29: =GETPIVOTDATA("GanoEquipo2",Hoja4!$D$3,"id2",CONCATENATE($B$29,M23)) -> 0 | N29: =GETPIVOTDATA("GanoEquipo2",Hoja4!$D$3,"id2",CONCATENATE($B$29,N23)) -> 0 | Q29: =GETPIVOTDATA("GanoEquipo2",Hoja4!$D$3,"id2",CONCATENATE($B$29,Q23)) -> 0 | S29: =SUM(C29:R29) -> 3
B30: Ecuador | C30: =GETPIVOTDATA("GanoEquipo2",Hoja4!$D$3,"id2",CONCATENATE($B$30,C23)) -> 0 | D30: =GETPIVOTDATA("GanoEquipo2",Hoja4!$D$3,"id2",CONCATENATE($B$30,D23)) -> 1 | F30: =GETPIVOTDATA("GanoEquipo2",Hoja4!$D$3,"id2",CONCATENATE($B$30,F23)) -> 1 | G30: =GETPIVOTDATA("GanoEquipo2",Hoja4!$D$3,"id2",CONCATENATE($B$30,G23)) -> 2 | S30: =SUM(C30:R30) -> 4
B31: Honduras | D31: =GETPIVOTDATA("GanoEquipo2",Hoja4!$D$3,"id2",CONCATENATE($B$31,D23)) -> 1 | E31: =GETPIVOTDATA("GanoEquipo2",Hoja4!$D$3,"id2",CONCATENATE($B$31,E23)) -> 1 | G31: =GETPIVOTDATA("GanoEquipo2",Hoja4!$D$3,"id2",CONCATENATE($B$31,G23)) -> 0 | H31: =GETPIVOTDATA("GanoEquipo2",Hoja4!$D$3,"id2",CONCATENATE($B$31,H23)) -> 0 | Q31: =GETPIVOTDATA("GanoEquipo2",Hoja4!$D$3,"id2",CONCATENATE($B$31,Q23)) -> 1 | S31: =SUM(C31:R31) -> 3
B32: Jamaica | C32: =GETPIVOTDATA("GanoEquipo2",Hoja4!$D$3,"id2",CONCATENATE($B$32,C23)) -> 0 | N32: =GETPIVOTDATA("GanoEquipo2",Hoja4!$D$3,"id2",CONCATENATE($B$32,N23)) -> 0 | Q32: =GETPIVOTDATA("GanoEquipo2",Hoja4!$D$3,"id2",CONCATENATE($B$32,Q23)) -> 0 | S32: =SUM(C32:R32) -> 0
B33: Japan | D33: =GETPIVOTDATA("GanoEquipo2",Hoja4!$D$3,"id2",CONCATENATE($B$33,D23)) -> 0 | N33: =GETPIVOTDATA("GanoEquipo2",Hoja4!$D$3,"id2",CONCATENATE($B$33,N23)) -> 0 | O33: =GETPIVOTDATA("GanoEquipo2",Hoja4!$D$3,"id2",CONCATENATE($B$33,O23)) -> 0 | S33: =SUM(C33:R33) -> 0
B34: Mexico | C34: =GETPIVOTDATA("GanoEquipo2",Hoja4!$D$3,"id2",CONCATENATE($B$34,C23)) -> 1 | D34: =GETPIVOTDATA("GanoEquipo2",Hoja4!$D$3,"id2",CONCATENATE($B$34,D23)) -> 0 | E34: =GETPIVOTDATA("GanoEquipo2",Hoja4!$D$3,"id2",CONCATENATE($B$34,E23)) -> 2 | F34: =GETPIVOTDATA("GanoEquipo2",Hoja4!$D$3,"id2",CONCATENATE($B$34,F23)) -> 3 | G34: =GETPIVOTDATA("GanoEquipo2",Hoja4!$D$3,"id2",CONCATENATE($B$34,G23)) -> 1 | I34: =GETPIVOTDATA("GanoEquipo2",Hoja4!$D$3,"id2",CONCATENATE($B$34,I23)) -> 4 | N34: =GETPIVOTDATA("GanoEquipo2",Hoja4!$D$3,"id2",CONCATENATE($B$34,N23)) -> 1 | O34: =GETPIVOTDATA("GanoEquipo2",Hoja4!$D$3,"id2",CONCATENATE($B$34,O23)) -> 2 | Q34: =GETPIVOTDATA("GanoEquipo2",Hoja4!$D$3,"id2",CONCATENATE($B$34,Q23)) -> 2 | R34: =GETPIVOTDATA("GanoEquipo2",Hoja4!$D$3,"id2",CONCATENATE($B$34,R23)) -> 2 | S34: =SUM(C34:R34) -> 18
B35: Paraguay | C35: =GETPIVOTDATA("GanoEquipo2",Hoja4!$D$3,"id2",CONCATENATE($B$35,C23)) -> 0 | D35: =GETPIVOTDATA("GanoEquipo2",Hoja4!$D$3,"id2",CONCATENATE($B$35,D23)) -> 7 | F35: =GETPIVOTDATA("GanoEquipo2",Hoja4!$D$3,"id2",CONCATENATE($B$35,F23)) -> 12 | G35: =GETPIVOTDATA("GanoEquipo2",Hoja4!$D$3,"id2",CONCATENATE($B$35,G23)) -> 5 | I35: =GETPIVOTDATA("GanoEquipo2",Hoja4!$D$3,"id2",CONCATENATE($B$35,I23)) -> 10 | S35: =SUM(C35:R35) -> 34
B36: Peru | C36: =GETPIVOTDATA("GanoEquipo2",Hoja4!$D$3,"id2",CONCATENATE($B$36,C23)) -> 3 | D36: =GETPIVOTDATA("GanoEquipo2",Hoja4!$D$3,"id2",CONCATENATE($B$36,D23)) -> 7 | F36: =GETPIVOTDATA("GanoEquipo2",Hoja4!$D$3,"id2",CONCATENATE($B$36,F23)) -> 6 | G36: =GETPIVOTDATA("GanoEquipo2",Hoja4!$D$3,"id2",CONCATENATE($B$36,G23)) -> 7 | I36: =GETPIVOTDATA("GanoEquipo2",Hoja4!$D$3,"id2",CONCATENATE($B$36,I23)) -> 8 | N36: =GETPIVOTDATA("GanoEquipo2",Hoja4!$D$3,"id2",CONCATENATE($B$36,N23)) -> 2 | S36: =SUM(C36:R36) -> 33
B37: United States | C37: =GETPIVOTDATA("GanoEquipo2",Hoja4!$D$3,"id2",CONCATENATE($B$37,C23)) -> 1 | D37: =GETPIVOTDATA("GanoEquipo2",Hoja4!$D$3,"id2",CONCATENATE($B$37,D23)) -> 0 | E37: =GETPIVOTDATA("GanoEquipo2",Hoja4!$D$3,"id2",CONCATENATE($B$37,E23)) -> 0 | F37: =GETPIVOTDATA("GanoEquipo2",Hoja4!$D$3,"id2",CONCATENATE($B$37,F23)) -> 1 | G37: =GETPIVOTDATA("GanoEquipo2",Hoja4!$D$3,"id2",CONCATENATE($B$37,G23)) -> 0 | I37: =GETPIVOTDATA("GanoEquipo2",Hoja4!$D$3,"id2",CONCATENATE($B$37,I23)) -> 0 | M37: =GETPIVOTDATA("GanoEquipo2",Hoja4!$D$3,"id2",CONCATENATE($B$37,M23)) -> 0 | N37: =GETPIVOTDATA("GanoEquipo2",Hoja4!$D$3,"id2",CONCATENATE($B$37,N23)) -> 0 | Q37: =GETPIVOTDATA("GanoEquipo2",Hoja4!$D$3,"id2",CONCATENATE($B$37,Q23)) -> 0 | R37: =GETPIVOTDATA("GanoEquipo2",Hoja4!$D$3,"id2",CONCATENATE($B$37,R23)) -> 0 | S37: =SUM(C37:R37) -> 2
B38: Uruguay | C38: =GETPIVOTDATA("GanoEquipo2",Hoja4!$D$3,"id2",CONCATENATE($B$38,C23)) -> 13 | D38: =GETPIVOTDATA("GanoEquipo2",Hoja4!$D$3,"id2",CONCATENATE($B$38,D23)) -> 13 | F38: =GETPIVOTDATA("GanoEquipo2",Hoja4!$D$3,"id2",CONCATENATE($B$38,F23)) -> 18 | G38: =GETPIVOTDATA("GanoEquipo2",Hoja4!$D$3,"id2",CONCATENATE($B$38,G23)) -> 6 | I38: =GETPIVOTDATA("GanoEquipo2",Hoja4!$D$3,"id2",CONCATENATE($B$38,I23)) -> 13 | N38: =GETPIVOTDATA("GanoEquipo2",Hoja4!$D$3,"id2",CONCATENATE($B$38,N23)) -> 14 | O38: =GETPIVOTDATA("GanoEquipo2",Hoja4!$D$3,"id2",CONCATENATE($B$38,O23)) -> 12 | S38: =SUM(C38:R38) -> 89
B39: Venezuela | C39: =GETPIVOTDATA("GanoEquipo2",Hoja4!$D$3,"id2",CONCATENATE($B$39,C23)) -> 0 | D39: =GETPIVOTDATA("GanoEquipo2",Hoja4!$D$3,"id2",CONCATENATE($B$39,D23)) -> 1 | F39: =GETPIVOTDATA("GanoEquipo2",Hoja4!$D$3,"id2",CONCATENATE($B$39,F23)) -> 1 | G39: =GETPIVOTDATA("GanoEquipo2",Hoja4!$D$3,"id2",CONCATENATE($B$39,G23)) -> 1 | I39: =GETPIVOTDATA("GanoEquipo2",Hoja4!$D$3,"id2",CONCATENATE($B$39,I23)) -> 1 | N39: =GETPIVOTDATA("GanoEquipo2",Hoja4!$D$3,"id2",CONCATENATE($B$39,N23)) -> 0 | O39: =GETPIVOTDATA("GanoEquipo2",Hoja4!$D$3,"id2",CONCATENATE($B$39,O23)) -> 1 | Q39: =GETPIVOTDATA("GanoEquipo2",Hoja4!$D$3,"id2",CONCATENATE($B$39,Q23)) -> 0 | S39: =SUM(C39:R39) -> 5
A41: Partidos Empatados
C42: Equipo 2 /Equipo 1
...

Sheet Hoja3
A1: Equipo1 | B1: Equipo2 | C1: GolE1 | D1: GolE2
A2: Chile | B2: Uruguay | C2: 0 | D2: 4 | E2: ="['"&A2&"','"&B2&"',"&C2&","&D2&"]," -> ['Chile','Uruguay',0,4], | F2: ="['"&B2&"','"&A2&"',"&D2&","&C2&"]," -> ['Uruguay','Chile',4,0],
A3: Argentina | B3: Chile | C3: 6 | D3: 1 | E3: ="['"&A3&"','"&B3&"',"&C3&","&D3&"]," -> ['Argentina','Chile',6,1], | F3: ="['"&B3&"','"&A3&"',"&D3&","&C3&"]," -> ['Chile','Argentina',1,6],
A4: Chile | B4: Brazil | C4: 1 | D4: 1 | E4: ="['"&A4&"','"&B4&"',"&C4&","&D4&"]," -> ['Chile','Brazil',1,1], | F4: ="['"&B4&"','"&A4&"',"&D4&","&C4&"]," -> ['Brazil','Chile',1,1],
A5: Argentina | B5: Brazil | C5: 1 | D5: 1 | E5: ="['"&A5&"','"&B5&"',"&C5&","&D5&"]," -> ['Argentina','Brazil',1,1], | F5: ="['"&B5&"','"&A5&"',"&D5&","&C5&"]," -> ['Brazil','Argentina',1,1],
A6: Uruguay | B6: Brazil | C6: 2 | D6: 1 | E6: ="['"&A6&"','"&B6&"',"&C6&","&D6&"]," -> ['Uruguay','Brazil',2,1], | F6: ="['"&B6&"','"&A6&"',"&D6&","&C6&"]," -> ['Brazil','Uruguay',1,2],
A7: Argentina | B7: Uruguay | C7: 0 | D7: 0 | E7: ="['"&A7&"','"&B7&"',"&C7&","&D7&"]," -> ['Argentina','Uruguay',0,0], | F7: ="['"&B7&"','"&A7&"',"&D7&","&C7&"]," -> ['Uruguay','Argentina',0,0],
A8: Chile | B8: Uruguay | C8: 0 | D8: 4 | E8: ="['"&A8&"','"&B8&"',"&C8&","&D8&"]," -> ['Chile','Uruguay',0,4], | F8: ="['"&B8&"','"&A8&"',"&D8&","&C8&"]," -> ['Uruguay','Chile',4,0],
A9: Argentina | B9: Brazil | C9: 4 | D9: 2 | E9: ="['"&A9&"','"&B9&"',"&C9&","&D9&"]," -> ['Argentina','Brazil',4,2], | F9: ="['"&B9&"','"&A9&"',"&D9&","&C9&"]," -> ['Brazil','Argentina',2,4],
A10: Argentina | B10: Chile | C10: 1 | D10: 0 | E10: ="['"&A10&"','"&B10&"',"&C10&","&D10&"]," -> ['Argentina','Chile',1,0], | F10: ="['"&B10&"','"&A10&"',"&D10&","&C10&"]," -> ['Chile','Argentina',0,1],
A11: Uruguay | B11: Brazil | C11: 4 | D11: 0 | E11: ="['"&A11&"','"&B11&"',"&C11&","&D11&"]," -> ['Uruguay','Brazil',4,0], | F11: ="['"&B11&"','"&A11&"',"&D11&","&C11&"]," -> ['Brazil','Uruguay',0,4],
A12: Chile | B12: Brazil | C12: 0 | D12: 5 | E12: ="['"&A12&"','"&B12&"',"&C12&","&D12&"]," -> ['Chile','Brazil',0,5], | F12: ="['"&B12&"','"&A12&"',"&D12&","&C12&"]," -> ['Brazil','Chile',5,0],
A13: Argentina | B13: Uruguay | C13: 0 | D13: 1 | E13: ="['"&A13&"','"&B13&"',"&C13&","&D13&"]," -> ['Argentina','Uruguay',0,1], | F13: ="['"&B13&"','"&A13&"',"&D13&","&C13&"]," -> ['Uruguay','Argentina',1,0],
... A746: Argentina | B746: Jamaica | C746: 1 | D746: 0 | E746: ="['"&A746&"','"&B746&"',"&C746&","&D746&"]," -> ['Argentina','Jamaica',1,0], | F746: ="['"&B746&"','"&A746&"',"&D746&","&C746&"]," -> ['Jamaica','Argentina',0,1],
A747: Paraguay | B747: Uruguay | C747: 1 | D747: 1 | E747: ="['"&A747&"','"&B747&"',"&C747&","&D747&"]" -> ['Paraguay','Uruguay',1,1] | F747: ="['"&B747&"','"&A747&"',"&D747&","&C747&"]" -> ['Uruguay','Paraguay',1,1]
